<?xml version="1.0" ?>
<!-- =================================================================================== -->
<!-- |    This document was autogenerated by xacro from src/cobot/urdf/cobot.xacro     | -->
<!-- |    EDITING THIS FILE BY HAND IS NOT RECOMMENDED                                 | -->
<!-- =================================================================================== -->
<robot name="cobot">
   
  <!-- ................................ BASE LINK .................................. -->
  <link name="base_link"/>

  <link name="base_footprint"/>

  <joint name="base_joint" type="fixed">
    <parent link="base_link"/>
    <child link="base_footprint"/>
    <origin rpy="0 0 0" xyz="0.0 0.0 -0.26"/>
  </joint>

  <link name="arm_base">
    <collision>
      <origin rpy="0 0 0" xyz="0 0 0"/>
      <geometry>
        <cylinder length="0.15" radius="0.15"/>
      </geometry>
    </collision>
    <visual>
      <origin rpy="0 0 0" xyz="0 0 0"/>
      <geometry>
        <cylinder length="0.1" radius="0.15"/>
      </geometry>
    </visual>
    <visual>
      <origin rpy="0 0 0" xyz="0 0 0"/>
      <geometry>
        <cylinder length="0.4" radius="0.1"/>
      </geometry>
    </visual>
    <inertial>
      <origin rpy="0 0 0" xyz="0 0 0"/>
      <mass value="5.0"/>
      <inertia ixx="0.000170625" ixy="0" ixz="0" iyy="0.000170625" iyz="0" izz="0.00028125"/>
    </inertial>
  </link>
  <joint name="arm_base_joint" type="fixed">
    <parent link="base_link"/>
    <child link="arm_base"/>
    <origin rpy="0 0 0" xyz="0.1 0 0.2"/>
  </joint>
  
  <link name="arm_link1">
    <collision>
      <origin rpy="0 0 0" xyz="0 0 0"/>
      <geometry>
        <cylinder length="0.15" radius="0.15"/>
      </geometry>
    </collision>
    <visual>
      <origin rpy="0 0 0" xyz="0 0 0"/>
      <geometry>
        <sphere radius="0.1"/>
      </geometry>
    </visual>
    <visual>
      <origin rpy="1.57 0 0" xyz="0 0.1 0"/>
      <geometry>
        <cylinder length="0.2" radius="0.1"/>
      </geometry>
    </visual>
    <inertial>
      <origin rpy="0 0 0" xyz="0 0 0"/>
      <mass value="2.0"/>
      <inertia ixx="0.000170625" ixy="0" ixz="0" iyy="0.000170625" iyz="0" izz="0.00028125"/>
    </inertial>
  </link>
  <joint name="arm_joint1" type="revolute">
    <parent link="arm_base"/>
    <child link="arm_link1"/>
    <origin rpy="0 0 0" xyz="0.0 0 0.2"/>
    <axis xyz="0 0 1"/>
    <limit effort="411" lower="-3.14" upper="3.14" velocity="1.57"/>
    <dynamics damping="60.0" friction="4.0"/>
  </joint>
  
  <link name="arm_link2">
    <collision>
      <origin rpy="0 0 0" xyz="0 0 0"/>
      <geometry>
        <cylinder length="0.15" radius="0.15"/>
      </geometry>
    </collision>
    <visual>
      <origin rpy="0 0 0" xyz="0 0 0"/>
      <geometry>
        <cylinder length="0.2" radius="0.1"/>
      </geometry>
    </visual>
    <visual>
      <origin rpy="1.57 0 0" xyz="0 0.35 0"/>
      <geometry>
        <cylinder length="0.7" radius="0.08"/>
      </geometry>
    </visual>
    <inertial>
      <origin rpy="0 0 0" xyz="0 0 0"/>
      <mass value="1.0"/>
      <inertia ixx="0.000170625" ixy="0" ixz="0" iyy="0.000170625" iyz="0" izz="0.00028125"/>
    </inertial>
  </link>
  <joint name="arm_joint2" type="revolute">
    <parent link="arm_link1"/>
    <child link="arm_link2"/>
    <origin rpy="1.57 0 0" xyz="0.0 0.3 0.0"/>
    <axis xyz="0 0 1"/>
    <limit effort="411" lower="-1.5" upper="1.5" velocity="1.57"/>
    <dynamics damping="60.0" friction="4.0"/>
  </joint>
  
  <link name="arm_link3">
    <collision>
      <origin rpy="0 0 0" xyz="0 0 0"/>
      <geometry>
        <cylinder length="0.15" radius="0.15"/>
      </geometry>
    </collision>
    <visual>
      <origin rpy="0 0 0" xyz="0 0 0"/>
      <geometry>
        <sphere radius="0.08"/>
      </geometry>
    </visual>
    <visual>
      <origin rpy="0 0 0" xyz="0.0 0 0.2"/>
      <geometry>
        <cylinder length="0.4" radius="0.08"/>
      </geometry>
    </visual>
    <visual>
      <origin rpy="1.57 0 0" xyz="0.0 0.4 0.3"/>
      <geometry>
        <cylinder length="0.8" radius="0.08"/>
      </geometry>
    </visual>
    <inertial>
      <origin rpy="0 0 0" xyz="0 0 0"/>
      <mass value="1.0"/>
      <inertia ixx="0.000170625" ixy="0" ixz="0" iyy="0.000170625" iyz="0" izz="0.00028125"/>
    </inertial>
  </link>
  <joint name="arm_joint3" type="revolute">
    <parent link="arm_link2"/>
    <child link="arm_link3"/>
    <origin rpy="0 0 0" xyz="0.0 0.7 0"/>
    <axis xyz="0 0 1"/>
    <limit effort="411" lower="-2.4" upper="2.4" velocity="1.57"/>
    <dynamics damping="60.0" friction="4.0"/>
  </joint>
  
  <link name="arm_link4">
    <collision>
      <origin rpy="0 0 0" xyz="0 0 0"/>
      <geometry>
        <cylinder length="0.15" radius="0.15"/>
      </geometry>
    </collision>
    <visual>
      <origin rpy="0 0 0" xyz="0 0 0"/>
      <geometry>
        <sphere radius="0.08"/>
      </geometry>
    </visual>
    <visual>
      <origin rpy="0 0 0" xyz="0.0 0 -0.1"/>
      <geometry>
        <cylinder length="0.2" radius="0.08"/>
      </geometry>
    </visual>
    <inertial>
      <origin rpy="0 0 0" xyz="0 0 0"/>
      <mass value="0.5"/>
      <inertia ixx="0.000170625" ixy="0" ixz="0" iyy="0.000170625" iyz="0" izz="0.00028125"/>
    </inertial>
  </link>
  <joint name="arm_joint4" type="revolute">
    <parent link="arm_link3"/>
    <child link="arm_link4"/>
    <origin rpy="0 0 0" xyz="0.0 0.8 0.3"/>
    <axis xyz="0 0 1"/>
    <limit effort="411" lower="-3.14" upper="3.14" velocity="1.57"/>
    <dynamics damping="60.0" friction="4.0"/>
  </joint>
  
  <link name="arm_link5">
    <collision>
      <origin rpy="0 0 0" xyz="0 0 0"/>
      <geometry>
        <cylinder length="0.15" radius="0.15"/>
      </geometry>
    </collision>
    <visual>
      <origin rpy="0 0 0" xyz="0 0 0"/>
      <geometry>
        <sphere radius="0.08"/>
      </geometry>
    </visual>
    <visual>
      <origin rpy="1.57 0 0" xyz="0.0 0.1 0.0"/>
      <geometry>
        <cylinder length="0.2" radius="0.08"/>
      </geometry>
    </visual>
    <visual>
      <origin rpy="0 0 0" xyz="0.0 0.2 0.0"/>
      <geometry>
        <cylinder length="0.2" radius="0.08"/>
      </geometry>
    </visual>
    <inertial>
      <origin rpy="0 0 0" xyz="0 0 0"/>
      <mass value="0.5"/>
      <inertia ixx="0.000170625" ixy="0" ixz="0" iyy="0.000170625" iyz="0" izz="0.00028125"/>
    </inertial>
  </link>
  <joint name="arm_joint5" type="revolute">
    <parent link="arm_link4"/>
    <child link="arm_link5"/>
    <origin rpy="0 0 0" xyz="0.0 0.0 -0.2"/>
    <axis xyz="0 1 0"/>
    <limit effort="411" lower="-3.14" upper="3.144" velocity="1.57"/>
    <dynamics damping="60.0" friction="4.0"/>
  </joint>

  <link name="arm_link6">
    <collision>
      <origin rpy="0 0 0" xyz="0 0 0"/>
      <geometry>
        <cylinder length="0.15" radius="0.15"/>
      </geometry>
    </collision>
    <visual>
      <origin rpy="0 0 0" xyz="0.0 0.0 0.0"/>
      <geometry>
        <cylinder length="0.1" radius="0.08"/>
      </geometry>
    </visual>
    <inertial>
      <origin rpy="0 0 0" xyz="0 0 0"/>
      <mass value="0.5"/>
      <inertia ixx="0.000170625" ixy="0" ixz="0" iyy="0.000170625" iyz="0" izz="0.00028125"/>
    </inertial>
  </link>
  <joint name="arm_joint6" type="revolute">
    <parent link="arm_link5"/>
    <child link="arm_link6"/>
    <origin rpy="0 0 0" xyz="0.0 0.2 0.15"/>
    <axis xyz="0 0 1"/>
    <limit effort="411" lower="0" upper="3.14" velocity="1.57"/>
    <dynamics damping="60.0" friction="4.0"/>
  </joint>
  <link name="right_gripper_finger_link">
    <collision>
      <origin rpy="0 0 0" xyz="0 0 0"/>
      <geometry>
        <box size="0.01 0.01 0.01"/>
      </geometry>
    </collision>
    <visual>
      <origin rpy="0 0 0" xyz="0.0 0.0 0.0"/>
      <geometry>
        <box size="0.05 0.025 0.1"/>
      </geometry>
    </visual>
    <inertial>
      <mass value="0.05"/>
      <inertia ixx="8.333333333333334e-07" ixy="0" ixz="0" iyy="8.333333333333334e-07" iyz="0" izz="8.333333333333334e-07"/>
    </inertial>
  </link>
  <joint name="right_gripper_finger_joint" type="prismatic">
    <parent link="arm_link6"/>
    <child link="right_gripper_finger_link"/>
    <origin rpy="0 0 0" xyz="0.0 0.05 0.1"/>
    <axis xyz="0 1 0"/>
    <limit effort="411" lower="-0.03" upper="0.03" velocity="1.57"/>
    <dynamics damping="60.0" friction="4.0"/>
  </joint>

  <link name="left_gripper_finger_link">
    <collision>
      <origin rpy="0 0 0" xyz="0 0 0"/>
      <geometry>
        <box size="0.01 0.01 0.01"/>
      </geometry>
    </collision>
    <visual>
      <origin rpy="0 0 0" xyz="0.0 0.0 0.0"/>
      <geometry>
        <box size="0.05 0.025 0.1"/>
      </geometry>
    </visual>
    <inertial>
      <mass value="0.05"/>
      <inertia ixx="8.333333333333334e-07" ixy="0" ixz="0" iyy="8.333333333333334e-07" iyz="0" izz="8.333333333333334e-07"/>
    </inertial>
  </link>
  <joint name="left_gripper_finger_joint" type="prismatic">
    <parent link="arm_link6"/>
    <child link="left_gripper_finger_link"/>
    <origin rpy="0 0 0" xyz="0.0 -0.05 0.1"/>
    <axis xyz="0 1 0"/>
    <limit effort="411" lower="-0.03" upper="0.03" velocity="1.57"/>
    <dynamics damping="60.0" friction="4.0"/>
  </joint>
  
  <ros2_control name="GazeboSystem" type="system">
    <hardware>
      <plugin>gazebo_ros2_control/GazeboSystem</plugin>
    </hardware>
    <joint name="arm_joint1">
      <command_interface name="position">
        <param name="min">-3.14</param>
        <param name="max">3.14</param>
      </command_interface>
      <command_interface name="velocity">
        <param name="min">-3.15</param>
        <param name="max">3.15</param>
      </command_interface>
      <state_interface name="position"/>
      <state_interface name="velocity"/>
      <state_interface name="effort"/>
      <param name="initial_position">0.0</param>
    </joint>
    <joint name="arm_joint2">
      <command_interface name="position">
        <param name="min">-3.14</param>
        <param name="max">3.14</param>
      </command_interface>
      <command_interface name="velocity">
        <param name="min">-3.15</param>
        <param name="max">3.15</param>
      </command_interface>
      <state_interface name="position"/>
      <state_interface name="velocity"/>
      <state_interface name="effort"/>
      <param name="initial_position">-1.57</param>
    </joint>
    <joint name="arm_joint3">
      <command_interface name="position">
        <param name="min">-3.14</param>
        <param name="max">3.14</param>
      </command_interface>
      <command_interface name="velocity">
        <param name="min">-3.15</param>
        <param name="max">3.15</param>
      </command_interface>
      <state_interface name="position"/>
      <state_interface name="velocity"/>
      <state_interface name="effort"/>
      <param name="initial_position">0.0</param>
    </joint>
    <joint name="arm_joint4">
      <command_interface name="position">
        <param name="min">-3.14</param>
        <param name="max">3.14</param>
      </command_interface>
      <command_interface name="velocity">
        <param name="min">-3.15</param>
        <param name="max">3.15</param>
      </command_interface>
      <state_interface name="position"/>
      <state_interface name="velocity"/>
      <state_interface name="effort"/>
      <param name="initial_position">0.0</param>
    </joint>
    <joint name="arm_joint5">
      <command_interface name="position">
        <param name="min">-3.14</param>
        <param name="max">3.14</param>
      </command_interface>
      <command_interface name="velocity">
        <param name="min">-3.15</param>
        <param name="max">3.15</param>
      </command_interface>
      <state_interface name="position"/>
      <state_interface name="velocity"/>
      <state_interface name="effort"/>
      <param name="initial_position">0.0</param>
    </joint>
    <joint name="arm_joint6">
      <command_interface name="position">
        <param name="min">-3.14</param>
        <param name="max">3.14</param>
      </command_interface>
      <command_interface name="velocity">
        <param name="min">-3.15</param>
        <param name="max">3.15</param>
      </command_interface>
      <state_interface name="position"/>
      <state_interface name="velocity"/>
      <state_interface name="effort"/>
      <param name="initial_position">0.0</param>
    </joint>
    <joint name="right_gripper_finger_joint">
      <command_interface name="position">
        <param name="min">-3.14</param>
        <param name="max">3.14</param>
      </command_interface>
      <command_interface name="velocity">
        <param name="min">-3.2</param>
        <param name="max">3.2</param>
      </command_interface>
      <state_interface name="position"/>
      <state_interface name="velocity"/>
      <state_interface name="effort"/>
      <param name="initial_position">0.0</param>
    </joint>
    <joint name="left_gripper_finger_joint">
      <command_interface name="position">
        <param name="min">-3.14</param>
        <param name="max">3.14</param>
      </command_interface>
      <command_interface name="velocity">
        <param name="min">-3.2</param>
        <param name="max">3.2</param>
      </command_interface>
      <state_interface name="position"/>
      <state_interface name="velocity"/>
      <state_interface name="effort"/>
      <param name="initial_position">0.0</param>
    </joint>
  </ros2_control>
</robot>
